<?xml version="1.0" encoding="utf-8"?>
<!-- This URDF was automatically created by SolidWorks to URDF Exporter! Originally created by Stephen Brawner (brawner@gmail.com) 
     Commit Version: 1.6.0-4-g7f85cfe  Build Version: 1.6.7995.38578
     For more information, please see http://wiki.ros.org/sw_urdf_exporter -->
<robot
  name="luci_devkit">
  
  <!-- Base footprint - fixed reference frame on the ground -->
  <link name="base_footprint">
    <visual>
      <origin xyz="0 0 0" rpy="0 0 0" />
      <geometry>
        <box size="0.001 0.001 0.001" />
      </geometry>
    </visual>
  </link>

  <!-- Joint connecting base_footprint to base_link -->
  <joint name="base_footprint_joint" type="fixed">
    <origin xyz="0 0 0" rpy="0 0 0" />
    <parent link="base_footprint"/>
    <child link="base_link"/>
  </joint>

  <link
    name="base_link">
    <inertial>
      <origin
        xyz="-3.34172222934376E-18 -0.0946712867904343 0.158397053532782"
        rpy="0 0 0" />
      <mass
        value="122.483916422456" />
      <inertia
        ixx="4.58595325954116"
        ixy="-2.69904318662155E-16"
        ixz="1.95290334027259E-16"
        iyy="3.52280414575617"
        iyz="1.55524701887057"
        izz="3.76088853405292" />
    </inertial>
    <visual>
      <origin
        xyz="0 0 0"
        rpy="0 0 0" />
      <geometry>
        <mesh
          filename="package://luci_transforms/meshes/ChairBase.STL" />
      </geometry>
      <material
        name="">
        <color
          rgba="0.647058823529412 0.619607843137255 0.588235294117647 1" />
      </material>
    </visual>
    <collision>
      <origin
        xyz="0 0 0"
        rpy="0 0 0" />
      <geometry>
        <mesh
          filename="package://luci_transforms/meshes/ChairBase.STL" />
      </geometry>
    </collision>
  </link>
  <link
    name="LeftDriveWheel">
    <inertial>
      <origin
        xyz="8.38080561673382E-08 -1.11145362982233E-07 0.0346748144637357"
        rpy="0 0 0" />
      <mass
        value="4.94231318671819" />
      <inertia
        ixx="0.0344026866789988"
        ixy="-1.31600826850514E-09"
        ixz="-1.35795715791044E-08"
        iyy="0.0344026791170553"
        iyz="3.98834708084824E-10"
        izz="0.0666994559804568" />
    </inertial>
    <visual>
      <origin
        xyz="0 0 0"
        rpy="0 0 0" />
      <geometry>
        <mesh
          filename="package://luci_transforms/meshes/LeftDriveWheel.STL" />
      </geometry>
      <material
        name="">
        <color
          rgba="0.235294117647059 0.235294117647059 0.235294117647059 1" />
      </material>
    </visual>
    <collision>
      <origin
        xyz="-0.2442 0 0"
        rpy="1.5708 0.56633 1.5708"/>
      <geometry>
        <mesh
          filename="package://luci_transforms/meshes/LeftDriveWheel.STL" />
      </geometry>
    </collision>
  </link>
  <joint
    name="DWL"
    type="continuous">
    <origin
      xyz="-0.2442 0 0"
      rpy="-1.5708 1.179 1.5708" />
    <parent
      link="base_link" />
    <child
      link="LeftDriveWheel" />
    <axis
      xyz="0 0 1" />
    <limit
      lower="0"
      upper="0"
      effort="0"
      velocity="0" />
  </joint>
  <link
    name="RightDriveWheel">
    <inertial>
      <origin
        xyz="8.38080561029293E-08 -1.11145362982279E-07 0.0346748144637356"
        rpy="0 0 0" />
      <mass
        value="4.94231318671818" />
      <inertia
        ixx="0.0344026866789987"
        ixy="-1.31600826850514E-09"
        ixz="-1.35795715703525E-08"
        iyy="0.0344026791170552"
        iyz="3.98834711733449E-10"
        izz="0.0666994559804567" />
    </inertial>
    <visual>
      <origin
        xyz="0 0 0"
        rpy="0 0 0" />
      <geometry>
        <mesh
          filename="package://luci_transforms/meshes/RightDriveWheel.STL" />
      </geometry>
      <material
        name="">
        <color
          rgba="0.235294117647059 0.235294117647059 0.235294117647059 1" />
      </material>
    </visual>
    <collision>
      <origin
        xyz="0.2442 0 0"
        rpy="1.5708 0.56633 1.5708" />
      <geometry>
        <mesh
          filename="package://luci_transforms/meshes/RightDriveWheel.STL" />
      </geometry>
    </collision>
  </link>
  <joint
    name="DWR"
    type="continuous">
    <origin
      xyz="0.2442 0 0"
      rpy="1.5708 0.56633 1.5708" />
    <parent
      link="base_link" />
    <child
      link="RightDriveWheel" />
    <axis
      xyz="0 0 1" />
    <limit
      lower="0"
      upper="0"
      effort="0"
      velocity="0" />
  </joint>
  <link
    name="LFCaster">
    <inertial>
      <origin
        xyz="5.28878921213227E-09 0.0173467771283716 -0.0468526389656749"
        rpy="0 0 0" />
      <mass
        value="0.531427045356941" />
      <inertia
        ixx="0.00125262438184538"
        ixy="2.6519899404736E-11"
        ixz="-1.07027502121536E-10"
        iyy="0.00156364640980983"
        iyz="0.000313736357874171"
        izz="0.000620519160680663" />
    </inertial>
    <visual>
      <origin
        xyz="-0 0 0"
        rpy="0 0 0" />
      <geometry>
        <mesh
          filename="package://luci_transforms/meshes/LFCaster.STL" />
      </geometry>
      <material
        name="">
        <color
          rgba="0.647058823529412 0.619607843137255 0.588235294117647 1" />
      </material>
    </visual>
    <collision>
      <origin
        xyz="-0.2615 0.32555 0.030997"
        rpy="-0.10599 0.01689 0.15744"  />
      <geometry>
        <mesh
          filename="package://luci_transforms/meshes/LFCaster.STL" />
      </geometry>
    </collision>
  </link>
  <joint
    name="LFC"
    type="continuous">
    <origin
      xyz="-0.2615 0.32555 0.030997"
      rpy="-0.10599 0.01689 0.15744" />
    <parent
      link="base_link" />
    <child
      link="LFCaster" />
    <axis
      xyz="0 0 1" />
    <limit
      lower="0"
      upper="0"
      effort="0"
      velocity="0" />
  </joint>
  <link
    name="LFWheel">
    <inertial>
      <origin
        xyz="0 -5.55111512312578E-17 -0.0304000000000001"
        rpy="0 0 0" />
      <mass
        value="1.88764295837445" />
      <inertia
        ixx="0.00317882687713603"
        ixy="1.35525271560688E-20"
        ixz="-1.01643953670516E-19"
        iyy="0.00317882687713603"
        iyz="-5.01443504774546E-19"
        izz="0.00543810769554551" />
    </inertial>
    <visual>
      <origin
        xyz="0 0 0"
        rpy="0 0 0" />
      <geometry>
        <mesh
          filename="package://luci_transforms/meshes/LFWheel.STL" />
      </geometry>
      <material
        name="">
        <color
          rgba="0.250980392156863 0.250980392156863 0.250980392156863 1" />
      </material>
    </visual>
    <collision>
      <origin
        xyz="0 0 0"
        rpy="0 0 0" />
      <geometry>
        <mesh
          filename="package://luci_transforms/meshes/LFWheel.STL" />
      </geometry>
    </collision>
  </link>
  <joint
    name="WHEELLF"
    type="continuous">
    <origin
      xyz="0.030403 0.03772 -0.11117"
      rpy="1.5708 1.4434 1.5708" />
    <parent
      link="LFCaster" />
    <child
      link="LFWheel" />
    <axis
      xyz="0 0 1" />
    <limit
      lower="0"
      upper="0"
      effort="0"
      velocity="0" />
  </joint>
  <link
    name="RFCaster">
    <inertial>
      <origin
        xyz="5.36165190023752E-09 0.0173467770089031 -0.046852638989923"
        rpy="0 0 0" />
      <mass
        value="0.531427044840236" />
      <inertia
        ixx="0.00125262438268293"
        ixy="2.66836413275209E-11"
        ixz="-1.08102058855412E-10"
        iyy="0.00156364640890881"
        iyz="0.000313736360139233"
        izz="0.000620519161218686" />
    </inertial>
    <visual>
      <origin
        xyz="0 0 0"
        rpy="0 0 0" />
      <geometry>
        <mesh
          filename="package://luci_transforms/meshes/RFCaster.STL" />
      </geometry>
      <material
        name="">
        <color
          rgba="0.647058823529412 0.619607843137255 0.588235294117647 1" />
      </material>
    </visual>
    <collision>
      <origin
        xyz="0.2615 0.32555 0.030997"
        rpy="-0.10563 0.019024 0.17753" />
      <geometry>
        <mesh
          filename="package://luci_transforms/meshes/RFCaster.STL" />
      </geometry>
    </collision>
  </link>
  <joint
    name="RFC"
    type="continuous">
    <origin
      xyz="0.2615 0.32555 0.030997"
      rpy="-0.10563 0.019024 0.17753" />
    <parent
      link="base_link" />
    <child
      link="RFCaster" />
    <axis
      xyz="0 0 1" />
    <limit
      lower="0"
      upper="0"
      effort="0"
      velocity="0" />
  </joint>
  <link
    name="RFWheel">
    <inertial>
      <origin
        xyz="0 0 -0.0304000000000001"
        rpy="0 0 0" />
      <mass
        value="1.88764295837445" />
      <inertia
        ixx="0.00317882687713603"
        ixy="4.33680868994202E-19"
        ixz="1.66018457661843E-19"
        iyy="0.00317882687713603"
        iyz="2.80367905541173E-19"
        izz="0.00543810769554552" />
    </inertial>
    <visual>
      <origin
        xyz="0 0 0"
        rpy="0 0 0" />
      <geometry>
        <mesh
          filename="package://luci_transforms/meshes/RFWheel.STL" />
      </geometry>
      <material
        name="">
        <color
          rgba="0.250980392156863 0.250980392156863 0.250980392156863 1" />
      </material>
    </visual>
    <collision>
      <origin
        xyz="0 0 0"
        rpy="0 0 0" />
      <geometry>
        <mesh
          filename="package://luci_transforms/meshes/RFWheel.STL" />
      </geometry>
    </collision>
  </link>
  <joint
    name="WHEELRF"
    type="continuous">
    <origin
      xyz="0.030403 0.03772 -0.11117"
      rpy="1.5708 1.258 1.5708" />
    <parent
      link="RFCaster" />
    <child
      link="RFWheel" />
    <axis
      xyz="0 0 1" />
    <limit
      lower="0"
      upper="0"
      effort="0"
      velocity="0" />
  </joint>
  <link
    name="LRCaster">
    <inertial>
      <origin
        xyz="4.98532537474006E-09 0.0173467748531272 -0.0468526400899979"
        rpy="0 0 0" />
      <mass
        value="0.531427025681135" />
      <inertia
        ixx="0.00125262438101401"
        ixy="2.25793039573043E-11"
        ixz="-1.01760806432791E-10"
        iyy="0.0015636463796136"
        iyz="0.000313736400342854"
        izz="0.00062051916797408" />
    </inertial>
    <visual>
      <origin
        xyz="0 0 0"
        rpy="0 0 0" />
      <geometry>
        <mesh
          filename="package://luci_transforms/meshes/LRCaster.STL" />
      </geometry>
      <material
        name="">
        <color
          rgba="0.647058823529412 0.619607843137255 0.588235294117647 1" />
      </material>
    </visual>
    <collision>
      <origin
        xyz="0 0 0"
        rpy="0 0 0" />
      <geometry>
        <mesh
          filename="package://luci_transforms/meshes/LRCaster.STL" />
      </geometry>
    </collision>
  </link>
  <joint
    name="LRC"
    type="continuous">
    <origin
      xyz="-0.20845 -0.38076 0.036912"
      rpy="-0.015267 0.030888 -2.0299" />
    <parent
      link="base_link" />
    <child
      link="LRCaster" />
    <axis
      xyz="0 0 1" />
    <limit
      lower="0"
      upper="0"
      effort="0"
      velocity="0" />
  </joint>
  <link
    name="LRWheel">
    <inertial>
      <origin
        xyz="1.38777878078145E-17 -2.77555756156289E-17 -0.0304000000000001"
        rpy="0 0 0" />
      <mass
        value="1.88764295837444" />
      <inertia
        ixx="0.00317882687713603"
        ixy="3.25260651745651E-19"
        ixz="1.6940658945086E-19"
        iyy="0.00317882687713603"
        iyz="1.38913403349705E-19"
        izz="0.00543810769554551" />
    </inertial>
    <visual>
      <origin
        xyz="0 0 0"
        rpy="0 0 0" />
      <geometry>
        <mesh
          filename="package://luci_transforms/meshes/LRWheel.STL" />
      </geometry>
      <material
        name="">
        <color
          rgba="0.250980392156863 0.250980392156863 0.250980392156863 1" />
      </material>
    </visual>
    <collision>
      <origin
        xyz="0 0 0"
        rpy="0 0 0" />
      <geometry>
        <mesh
          filename="package://luci_transforms/meshes/LRWheel.STL" />
      </geometry>
    </collision>
  </link>
  <joint
    name="WHEELLR"
    type="continuous">
    <origin
      xyz="0.030403 0.03772 -0.11117"
      rpy="-1.5708 1.0052 -1.5708" />
    <parent
      link="LRCaster" />
    <child
      link="LRWheel" />
    <axis
      xyz="0 0 1" />
    <limit
      lower="0"
      upper="0"
      effort="0"
      velocity="0" />
  </joint>
  <link
    name="RRCaster">
    <inertial>
      <origin
        xyz="4.96052365850375E-09 0.0173467749190128 -0.0468526401060469"
        rpy="0 0 0" />
      <mass
        value="0.531427025422204" />
      <inertia
        ixx="0.00125262438018788"
        ixy="2.25538810008406E-11"
        ixz="-1.01401547479435E-10"
        iyy="0.00156364637935991"
        iyz="0.000313736399108148"
        izz="0.000620519167494877" />
    </inertial>
    <visual>
      <origin
        xyz="0 0 0"
        rpy="0 0 0" />
      <geometry>
        <mesh
          filename="package://luci_transforms/meshes/RRCaster.STL" />
      </geometry>
      <material
        name="">
        <color
          rgba="0.647058823529412 0.619607843137255 0.588235294117647 1" />
      </material>
    </visual>
    <collision>
      <origin
        xyz="0 0 0"
        rpy="0 0 0" />
      <geometry>
        <mesh
          filename="package://luci_transforms/meshes/RRCaster.STL" />
      </geometry>
    </collision>
  </link>
  <joint
    name="RRC"
    type="continuous">
    <origin
      xyz="0.20845 -0.38076 0.036912"
      rpy="-0.014894 0.031069 -2.0179" />
    <parent
      link="base_link" />
    <child
      link="RRCaster" />
    <axis
      xyz="0 0 1" />
    <limit
      lower="0"
      upper="0"
      effort="0"
      velocity="0" />
  </joint>
  <link
    name="RRWheel">
    <inertial>
      <origin
        xyz="-5.55111512312578E-17 2.77555756156289E-17 -0.0304"
        rpy="0 0 0" />
      <mass
        value="1.88764295837445" />
      <inertia
        ixx="0.00317882687713603"
        ixy="-2.71050543121376E-20"
        ixz="6.28498446862691E-19"
        iyy="0.00317882687713603"
        iyz="9.48676900924816E-20"
        izz="0.00543810769554551" />
    </inertial>
    <visual>
      <origin
        xyz="0 0 0"
        rpy="0 0 0" />
      <geometry>
        <mesh
          filename="package://luci_transforms/meshes/RRWheel.STL" />
      </geometry>
      <material
        name="">
        <color
          rgba="0.250980392156863 0.250980392156863 0.250980392156863 1" />
      </material>
    </visual>
    <collision>
      <origin
        xyz="0 0 0"
        rpy="0 0 0" />
      <geometry>
        <mesh
          filename="package://luci_transforms/meshes/RRWheel.STL" />
      </geometry>
    </collision>
  </link>
  <joint
    name="WHEELRR"
    type="continuous">
    <origin
      xyz="-0.030402 0.03772 -0.11117"
      rpy="1.5708 0.14984 -1.5708" />
    <parent
      link="RRCaster" />
    <child
      link="RRWheel" />
    <axis
      xyz="0 0 1" />
    <limit
      lower="0"
      upper="0"
      effort="0"
      velocity="0" />
  </joint>
</robot>